<?xml version="1.0"?>
<robot name="test_robot">
  <link name="base_link">
    <visual name='visual'>
      <geometry>
        <box size="0.075 0.075 0.095"/>
      </geometry>
      <material name="black">
        <color rgba="0 0 0 1"/>
      </material>
    </visual>
    <collision>
      <geometry>
        <box size="0.075 0.075 0.095"/>
      </geometry>
    </collision>
    <inertial>
      <origin xyz="0 0 -0.05" rpy="0 0 0"/>
      <mass value="0.2"/>
      <inertia ixx="1e-2" ixy="0" ixz="0" iyy="1e-2" iyz="0" izz="1e-2"/>
    </inertial>
  </link>
  
  <link name="left_wheel_link">
    <visual name="visual">
      <geometry>
        <cylinder radius="0.0375" length="0.01"/>
      </geometry>
      <origin xyz="0 0 0" rpy="0 0 0"/>
      <material name="blue">
        <color rgba="0 0 .8 1"/>
      </material>
    </visual>
    <collision>
      <geometry>
        <cylinder radius="0.0375" length="0.01"/>
      </geometry>
    </collision>
    <inertial>
      <mass value="0.05"/>
      <inertia ixx="7e-5" ixy="0.0" ixz="0.0" iyy="7e-5" iyz="0.0" izz="7e-5"/>
    </inertial>
  </link>
  
  <link name="right_wheel_link">
    <visual name="visual">
      <geometry>
        <cylinder radius="0.0375" length="0.01"/>
      </geometry>
      <origin xyz="0 0 0" rpy="0 0 0"/>
      <material name="blue">
        <color rgba="0 0 .8 1"/>
      </material>
    </visual>
    <collision>
      <geometry>
        <cylinder radius="0.0375" length="0.01"/>
      </geometry>
    </collision>
    <inertial>
      <mass value="0.05"/>
      <inertia ixx="7e-5" ixy="0.0" ixz="0.0" iyy="7e-5" iyz="0.0" izz="7e-5"/>
    </inertial>
  </link>

  <joint name="left_joint" type="continuous">
    <parent link="base_link"/>
    <child link="left_wheel_link"/>
    <origin xyz="0 0.0375 -0.02" rpy="-1.57 0 0"/>
    <axis xyz="0 0 1" />
  </joint>
  
  <joint name="right_joint" type="continuous">
    <parent link="base_link"/>
    <child link="right_wheel_link"/>
    <origin xyz="0 -0.0375 -0.02" rpy="1.57 0 0"/>
    <axis xyz="0 0 1" />
  </joint>
  
  <gazebo>
    <plugin name="differential_drive_controller" filename="libgazebo_ros_diff_drive.so">
      <alwaysOn>true</alwaysOn>
      <updateRate>1000</updateRate>
      <leftJoint>left_joint</leftJoint>
      <rightJoint>right_joint</rightJoint>
      <wheelSeparation>0.075</wheelSeparation>
      <wheelDiameter>0.075</wheelDiameter>
      <torque>0.2</torque>
      <commandTopic>cmd_vel</commandTopic>
      <odometryTopic>odom</odometryTopic>
      <odometryFrame>odom</odometryFrame>
      <robotBaseFrame>base_link</robotBaseFrame>
    </plugin>
  </gazebo>
</robot>
